<robot name="onshape">
    <link name="coupler">
        <visual>
            <origin xyz="0.0076185226336969169569 0.01602287057000122833 -0.026352584457783326949"
                rpy="0 -0 0" />
            <geometry>
                <mesh filename="package:///coupler.stl" />
            </geometry>
            <material name="coupler_material">
                <color
                    rgba="0.61568627450980395466 0.81176470588235294379 0.92941176470588238168 1.0" />
            </material>
        </visual>
        <collision>
            <origin xyz="0.0076185226336969169569 0.01602287057000122833 -0.026352584457783326949"
                rpy="0 -0 0" />
            <geometry>
                <mesh filename="package:///coupler.stl" />
            </geometry>
        </collision>
        <inertial>
            <origin xyz="0.059457331089903711629 0.04473059794826811375 -0.026352584457783306132"
                rpy="0 0 0" />
            <mass value="0.52500488643203435668" />
            <inertia ixx="0.0017154388189821222557" ixy="-0.0007995744266173912063" ixz="0"
                iyy="0.0026160173506496889675" iyz="0" izz="0.0029912187796853682668" />
        </inertial>
    </link>

    <link name="body">
        <visual>
            <origin xyz="-6.9388939039072283776e-18 -0.10159999999999994036 0.09525000000000001521"
                rpy="-1.570796326794896558 -1.570796326794896558 0" />
            <geometry>
                <mesh filename="package:///body.stl" />
            </geometry>
            <material name="body_material">
                <color
                    rgba="0.61568627450980395466 0.81176470588235294379 0.92941176470588238168 1.0" />
            </material>
        </visual>
        <collision>
            <origin xyz="-6.9388939039072283776e-18 -0.10159999999999994036 0.09525000000000001521"
                rpy="-1.570796326794896558 -1.570796326794896558 0" />
            <geometry>
                <mesh filename="package:///body.stl" />
            </geometry>
        </collision>
        <inertial>
            <origin xyz="0.00094664124949074362168 0.0019566509168293666487 0.095175461021671584061"
                rpy="0 0 0" />
            <mass value="71.513617955613540289" />
            <inertia ixx="2.7695768268605731599" ixy="-0.012891515253177195446"
                ixz="-5.0461204235767260229e-06" iyy="4.9414740165599875255"
                iyz="-1.0430029495049975829e-05" izz="2.7059577965441983238" />
        </inertial>
    </link>

    <joint name="rev_x" type="revolute">
        <origin xyz="0.0076185226336969169569 0.016022870570001249146 -0.026352584457783323479"
            rpy="1.570796326794896558 -0 1.570796326794896558" />
        <parent link="coupler" />
        <child link="body" />
        <axis xyz="0 0 1" />
        <limit effort="1.5" velocity="22" />
        <joint_properties friction="0.0" />
    </joint>

    <link name="sleeve">
        <visual>
            <origin xyz="0 -3.4694469519536141888e-18 -0.076200000000000017719"
                rpy="-1.570796326794896558 -0 0" />
            <geometry>
                <mesh filename="package:///sleeve.stl" />
            </geometry>
            <material name="sleeve_material">
                <color
                    rgba="0.61568627450980395466 0.81176470588235294379 0.92941176470588238168 1.0" />
            </material>
        </visual>
        <collision>
            <origin xyz="0 -3.4694469519536141888e-18 -0.076200000000000017719"
                rpy="-1.570796326794896558 -0 0" />
            <geometry>
                <mesh filename="package:///sleeve.stl" />
            </geometry>
        </collision>
        <inertial>
            <origin
                xyz="-1.278090274607719524e-08 7.890502696409230085e-09 -0.060135671624197417628"
                rpy="0 0 0" />
            <mass value="0.4777148575757113047" />
            <inertia ixx="0.00098751957755369027328" ixy="1.8087162374182167824e-10"
                ixz="-5.2382929832911515583e-11" iyy="0.00071438567656500258796"
                iyz="-3.233310208673502129e-10" izz="0.00070475956605723429505" />
        </inertial>
    </link>

    <link name="pogo">
        <visual>
            <origin xyz="0 3.4694469519536141888e-18 -0.91440000000000010161" rpy="0 -0 0" />
            <geometry>
                <mesh filename="package:///pogo.stl" />
            </geometry>
            <material name="pogo_material">
                <color
                    rgba="0.61568627450980395466 0.81176470588235294379 0.92941176470588238168 1.0" />
            </material>
        </visual>
        <collision>
            <origin xyz="0 3.4694469519536141888e-18 -0.91440000000000010161" rpy="0 -0 0" />
            <geometry>
                <mesh filename="package:///pogo.stl" />
            </geometry>
        </collision>
        <inertial>
            <origin
                xyz="4.3194544932116136525e-19 4.6359230281414684632e-18 -0.45403610139860128836"
                rpy="0 0 0" />
            <mass value="1.0890939243757413735" />
            <inertia ixx="0.074944292622089278555" ixy="0" ixz="0" iyy="0.074944292622089278555"
                iyz="0" izz="0.00019706467785043167815" />
        </inertial>
    </link>

    <joint name="cyl_z" type="revolute">
        <origin xyz="0 -0.063500000000000000888 -0.076200000000000017719"
            rpy="1.570796326794896558 -0 0" />
        <parent link="sleeve" />
        <child link="pogo" />
        <axis xyz="0 0 1" />
        <limit effort="1.5" velocity="22" />
        <joint_properties friction="0.0" />
    </joint>

    <joint name="rev_y" type="revolute">
        <origin xyz="0.10286852263369694604 0.092222870570001252988 -0.026352584457783316541"
            rpy="-1.570796326794896558 -0 0" />
        <parent link="coupler" />
        <child link="sleeve" />
        <axis xyz="0 0 1" />
        <limit effort="1.5" velocity="22" />
        <joint_properties friction="0.0" />
    </joint>


</robot>