<?xml version="1.0"?>
<robot xmlns:xacro="http://www.ros.org/wiki/xacro" name="hopper">

    <!-- BASE LINK -->

    <link name="base_link">
    
    </link>

    <!-- BODY LINK -->

    <joint name="body_joint" type="fixed">
        <parent link="base_link" />
        <child link="body" />
        <origin xyz="0.0 0.0 0.0" rpy="0 0 1.57079632679489" />
    </joint>

    <link name="body">
        <visual>
            <origin xyz="0 0 0" rpy="0 0 0" />
            <geometry>
                <mesh filename="package:///body.stl" />
            </geometry>
            <material name="body_material">
                <color
                    rgba="0.61568627450980395466 0.81176470588235294379 0.92941176470588238168 1.0" />
            </material>
        </visual>
        <collision>
            <origin xyz="0 0 0" rpy="0 0 0" />
            <geometry>
                <mesh filename="package:///body.stl" />
            </geometry>
        </collision>
        <inertial>
            <origin xyz="-7.4538978328428899403e-05 0.00094664124949074969322 0.10355665091682933476" rpy="0 0 0" />
            <mass value="71.513617955613540289" />
            <inertia ixx="2.7059577965441987679" ixy="-5.0461204235837386087e-06"
                ixz="-1.0430029495029113408e-05" iyy="2.7695768268605731599"
                iyz="-0.01289151525317717116" izz="4.9414740165599875255" />
        </inertial>
    </link>

    <!-- COUPLER LINK -->

    <link name="coupler">
        <visual>
            <origin xyz="-2.0816681711721685133e-17 0 0.0063499999999999945377"
                rpy="1.570796326794896558 1.570796326794896558 0" />
            <geometry>
                <mesh filename="package:///coupler.stl" />
            </geometry>
            <material name="coupler_material">
                <color
                    rgba="0.61568627450980395466 0.81176470588235294379 0.92941176470588238168 1.0" />
            </material>
        </visual>
        <collision>
            <origin xyz="-2.0816681711721685133e-17 0 0.0063499999999999945377"
                rpy="1.570796326794896558 1.570796326794896558 0" />
            <geometry>
                <mesh filename="package:///coupler.stl" />
            </geometry>
        </collision>
        <inertial>
            <origin
                xyz="0.028707727378266875012 -1.6124666532645141538e-17 -0.045488808456206786257"
                rpy="0 0 0" />
            <mass value="0.52500488643203435668" />
            <inertia ixx="0.0026160173506496889675" ixy="0" ixz="0.00079957442661739131472"
                iyy="0.0029912187796853669658" iyz="0" izz="0.0017154388189821222557" />
        </inertial>
    </link>

    <!-- SLEEVE LINK -->

    <link name="sleeve">
        <visual>
            <origin xyz="-3.0814879110195773649e-33 0 -0.076200000000000003841"
                rpy="-1.570796326794896558 -0 0" />
            <geometry>
                <mesh filename="package:///sleeve.stl" />
            </geometry>
            <material name="sleeve_material">
                <color
                    rgba="0.61568627450980395466 0.81176470588235294379 0.92941176470588238168 1.0" />
            </material>
        </visual>
        <collision>
            <origin xyz="-3.0814879110195773649e-33 0 -0.076200000000000003841"
                rpy="-1.570796326794896558 -0 0" />
            <geometry>
                <mesh filename="package:///sleeve.stl" />
            </geometry>
        </collision>
        <inertial>
            <origin
                xyz="-1.278090274607719524e-08 7.890502699878677037e-09 -0.060135671624197403751"
                rpy="0 0 0" />
            <mass value="0.4777148575757113047" />
            <inertia ixx="0.00098751957755369027328" ixy="1.8087162374182167824e-10"
                ixz="-5.2382929832911515583e-11" iyy="0.00071438567656500258796"
                iyz="-3.233310208673502129e-10" izz="0.00070475956605723429505" />
        </inertial>
    </link>

    <!-- POGO LINK -->

    <link name="pogo">
        <visual>
            <origin xyz="0 -1.1664760761878542743e-18 -0.91440000000000010161" rpy="0 -0 0" />
            <geometry>
                <mesh filename="package:///pogo.stl" />
            </geometry>
            <material name="pogo_material">
                <color
                    rgba="0.61568627450980395466 0.81176470588235294379 0.92941176470588238168 1.0" />
            </material>
        </visual>
        <collision>
            <origin xyz="0 -1.1664760761878542743e-18 -0.91440000000000010161" rpy="0 -0 0" />
            <geometry>
                <mesh filename="package:///pogo.stl" />
            </geometry>
        </collision>
        <inertial>
            <origin
                xyz="4.3194544932116136525e-19 -1.9259299443872358531e-34 -0.45403610139860128836"
                rpy="0 0 0" />
            <mass value="1.0890939243757413735" />
            <inertia ixx="0.074944292622089278555" ixy="0.0" ixz="0.0" iyy="0.074944292622089278555"
                iyz="0.0" izz="0.00019706467785043167815" />
        </inertial>
    </link>

    <joint name="pri_z" type="prismatic">
        <origin xyz="3.4694469519536141888e-18 -0.063500000000000070277 -0.076200000000000003841"
            rpy="1.570796326794896558 -0 0" />
        <parent link="sleeve" />
        <child link="pogo" />
        <axis xyz="0 0 1" />
        <limit effort="1.5" velocity="22" />
        <joint_properties friction="0.0" />
    </joint>

    <joint name="rev_y" type="revolute">
        <origin xyz="0.076199999999999989964 -1.3877787807814456755e-17 -0.088900000000000006795"
            rpy="-0 1.570796326794896558 0" />
        <parent link="coupler" />
        <child link="sleeve" />
        <axis xyz="0 0 1" />
        <limit effort="1.5" velocity="22" />
        <joint_properties friction="0.0" />
    </joint>

    <joint name="rev_x" type="revolute">
        <origin xyz="-0.088900000000000020672 -5.2041704279304212832e-18 0.10159999999999994036"
            rpy="-1.570796326794896558 -0 1.57079632679489678" />
        <parent link="body" />
        <child link="coupler" />
        <axis xyz="0 0 1" />
        <limit effort="1.5" velocity="22" />
        <joint_properties friction="0.0" />
    </joint>
</robot>